<mujoco model="sdog">
  <compiler angle="radian" meshdir="../meshes"/>
  <size njmax="500" nconmax="100" />
  <option gravity='0 0 -9.806' iterations='50' solver='Newton' timestep='0.002'/>
  <default>
        <geom contype="1" conaffinity="1" friction="0.6 0.3 0.3" rgba="0.5 0.6 0.7 1" margin="0.001" group="0"/>
        <light castshadow="false" diffuse="1 1 1"/>
        <motor ctrlrange="-33.5 33.5" ctrllimited="true"/>
        <camera fovy="60"/>
        <joint damping="0.05" armature="0.01" frictionloss="0.05"/>
  </default>
  <asset>
    <mesh name="base" file="base.STL"/>
    <mesh name="body" file="body.STL"/>
    <mesh name="fr_hip" file="fr_hip.STL"/>
    <mesh name="fr_thigh" file="fr_thigh.STL"/>
    <mesh name="fr_calf" file="fr_calf.STL"/>
    <mesh name="fr_foot" file="fr_foot.STL"/>
    <mesh name="fl_hip" file="fl_hip.STL"/>
    <mesh name="fl_thigh" file="fl_thigh.STL"/>
    <mesh name="fl_calf" file="fl_calf.STL"/>
    <mesh name="fl_foot" file="fl_foot.STL"/>
    <mesh name="br_hip" file="br_hip.STL"/>
    <mesh name="br_thigh" file="br_thigh.STL"/>
    <mesh name="br_calf" file="br_calf.STL"/>
    <mesh name="br_foot" file="br_foot.STL"/>
    <mesh name="bl_hip" file="bl_hip.STL"/>
    <mesh name="bl_thigh" file="bl_thigh.STL"/>
    <mesh name="bl_calf" file="bl_calf.STL"/>
    <mesh name="bl_foot" file="bl_foot.STL"/>
    <texture type="skybox" builtin="gradient" rgb1=".3 .5 .7" rgb2="0 0 0" width="512" height="512"/>
    <texture name="grid" type="2d" builtin="checker" width="512" height="512" rgb1=".1 .2 .3" rgb2=".2 .3 .4"/>
    <material name="grid" texture="grid" texrepeat="1 1" texuniform="true" reflectance=".2"/>
  </asset>

  <worldbody>
    <geom name="floor" pos="0 0 0" size="0 0 0.05" type="plane" material="grid" condim="3"/>
    <light name="spotlight" mode="fixed" pos="0 0 3" dir="0 0 -1" diffuse=".8 .8 .8" specular=".3 .3 .3" cutoff="100" exponent="30"/>
    <light castshadow="false" directional="true" diffuse=".3 .3 .3" specular="0.3 0.3 0.3" pos="-1 -1 1" dir="1 1 -1"/>
    <light directional="true" diffuse=".3 .3 .3" specular="0.3 0.3 0.3" pos="1 -1 1" dir="-1 1 -1"/>
    <light castshadow="false" directional="true" diffuse=".3 .3 .3" specular="0.3 0.3 0.3" pos="0 1 1" dir="0 -1 -1"/>
    <body name="trunk" pos="0 0 0.23">
      <freejoint name="root"/>
      <geom type="mesh" rgba="0.89804 0.91765 0.92941 1" mesh="base"/>
      <geom type="mesh" rgba="0.8902 0.8902 0.91373 1" mesh="body"/>
      <body name="fr_hip" pos="0.062526 -0.02085 0">
        <inertial pos="0.0023257 -0.025249 0.0055137" quat="0.557125 0.417005 -0.429525 0.575523" mass="0.01059" diaginertia="4.59415e-06 4.13295e-06 1.2864e-06"/>
        <joint name="fr_hip_joint" pos="0 0 0" axis="1 0 0" range="-0.8 0.8" actuatorfrcrange="-0.45 0.45"/>
        <geom type="mesh" rgba="0.8902 0.8902 0.91373 1" mesh="fr_hip"/>
        <body name="fr_thigh" pos="0.00031911 -0.03686 0">
          <inertial pos="-5.894e-05 0.0027005 -0.028881" quat="0.993505 0.113762 0.000832863 -0.00225745" mass="0.045112" diaginertia="1.7194e-05 1.71342e-05 3.52919e-06"/>
          <joint name="fr_thigh_joint" pos="0 0 0" axis="0 1 0" range="-1 2" actuatorfrcrange="-0.45 0.45"/>
          <geom type="mesh" rgba="0.8902 0.8902 0.91373 1" mesh="fr_thigh"/>
          <body name="fr_calf" pos="-1.4535e-05 0 -0.059049">
            <inertial pos="0.000214756 -0.00127643 -0.0394026" quat="0.758783 0.0217934 -0.0312341 0.650229" mass="0.014489" diaginertia="9.26291e-06 9.11254e-06 6.36044e-07"/>
            <joint name="fr_calf_joint" pos="0 0 0" axis="0 1 0" range="-2.69 -0.5" actuatorfrcrange="-0.45 0.45"/>
            <geom type="mesh" rgba="0.8902 0.8902 0.91373 1" mesh="fr_calf"/>
            <geom pos="0 0 -0.065878" quat="1 0 0 0" type="mesh" rgba="0.8902 0.8902 0.91373 1" mesh="fr_foot"/>
          </body>
        </body>
      </body>
      <body name="fl_hip" pos="0.062526 0.020224 0">
        <inertial pos="0.00232573 0.025876 0.00551368" quat="0.417008 0.557126 -0.57552 0.429525" mass="0.0105904" diaginertia="4.59417e-06 4.13298e-06 1.28639e-06"/>
        <joint name="fl_hip_joint" pos="0 0 0" axis="1 0 0" range="-0.8 0.8" actuatorfrcrange="-0.45 0.45"/>
        <geom type="mesh" rgba="0.890196 0.890196 0.913725 1" mesh="fl_hip"/>
        <body name="fl_thigh" pos="0.00031911 0.037482 0">
          <inertial pos="-5.9763e-05 -0.0026948 -0.028882" quat="0.993498 -0.113681 0.00125127 0.00607789" mass="0.045114" diaginertia="1.7197e-05 1.71363e-05 3.53005e-06"/>
          <joint name="fl_thigh_joint" pos="0 0 0" axis="0 1 0" range="-1 2" actuatorfrcrange="-0.45 0.45"/>
          <geom type="mesh" rgba="0.8902 0.8902 0.91373 1" mesh="fl_thigh"/>
          <body name="fl_calf" pos="-1.4535e-05 0 -0.059049">
            <inertial pos="0.000214512 0.00128085 -0.0394066" quat="0.650178 -0.0312294 0.0218028 0.758827" mass="0.0144904" diaginertia="9.26265e-06 9.11247e-06 6.36453e-07"/>
            <joint name="fl_calf_joint" pos="0 0 0" axis="0 1 0" range="-2.69 -0.5" actuatorfrcrange="-0.45 0.45"/>
            <geom type="mesh" rgba="0.890196 0.890196 0.913725 1" mesh="fl_calf"/>
            <geom pos="-0.00030458 0 -0.065887" quat="1 0 0 0" type="mesh" rgba="0.890196 0.890196 0.913725 1" mesh="fl_foot"/>
          </body>
        </body>
      </body>
      <body name="br_hip" pos="-0.05616 -0.02085 0">
        <inertial pos="-0.00967871 -0.025876 0.00551365" quat="0.557124 0.417006 -0.429526 0.575522" mass="0.0105904" diaginertia="4.59417e-06 4.13299e-06 1.28639e-06"/>
        <joint name="br_hip_joint" pos="0 0 0" axis="1 0 0" range="-0.8 0.8" actuatorfrcrange="-0.45 0.45"/>
        <geom type="mesh" rgba="0.890196 0.890196 0.913725 1" mesh="br_hip"/>
        <body name="br_thigh" pos="-0.011685 -0.03686 0">
          <inertial pos="-5.894e-05 0.0020738 -0.028881" quat="0.993505 0.113762 0.000832863 -0.00225745" mass="0.045112" diaginertia="1.7194e-05 1.71342e-05 3.52919e-06"/>
          <joint name="br_thigh_joint" pos="0 0 0" axis="0 1 0" range="-1 2" actuatorfrcrange="-0.45 0.45"/>
          <geom type="mesh" rgba="0.8902 0.8902 0.91373 1" mesh="br_thigh"/>
          <body name="br_calf" pos="0 0 -0.059063">
            <inertial pos="0.000394005 -0.00190142 -0.039386" quat="0.758635 0.0202126 -0.0331094 0.65036" mass="0.0144888" diaginertia="9.26298e-06 9.11248e-06 6.36114e-07"/>
            <joint name="br_calf_joint" pos="0 0 0" axis="0 1 0" range="-2.69 -0.5" actuatorfrcrange="-0.45 0.45"/>
            <geom type="mesh" rgba="0.890196 0.890196 0.913725 1" mesh="br_calf"/>
            <geom pos="0 0 -0.065864" quat="1 0 0 0" type="mesh" rgba="0.890196 0.890196 0.913725 1" mesh="br_foot"/>
          </body>
        </body>
      </body>
      <body name="bl_hip" pos="-0.067842 0.02085 0">
        <inertial pos="0.00200326 0.025876 0.00551368" quat="0.417008 0.557126 -0.57552 0.429525" mass="0.0105904" diaginertia="4.59417e-06 4.13298e-06 1.28639e-06"/>
        <joint name="bl_hip_joint" pos="0 0 0" axis="1 0 0" range="-0.8 0.8" actuatorfrcrange="-0.45 0.45"/>
        <geom type="mesh" rgba="0.890196 0.890196 0.913725 1" mesh="bl_hip"/>
        <body name="bl_thigh" pos="0 0.036855 0">
          <inertial pos="-5.9763e-05 -0.0020681 -0.028882" quat="0.993498 -0.113681 0.00125127 0.00607789" mass="0.045114" diaginertia="1.7197e-05 1.71363e-05 3.53005e-06"/>
          <joint name="bl_thigh_joint" pos="0 0 0" axis="0 1 0" range="-1 2" actuatorfrcrange="-0.45 0.45"/>
          <geom type="mesh" rgba="0.8902 0.8902 0.91373 1" mesh="bl_thigh"/>
          <body name="bl_calf" pos="0 0 -0.059063">
            <inertial pos="0.000393776 0.00190583 -0.0393902" quat="0.65028 -0.0331044 0.0202238 0.758703" mass="0.0144904" diaginertia="9.26264e-06 9.1124e-06 6.36524e-07"/>
            <joint name="bl_calf_joint" pos="0 0 0" axis="0 1 0" range="-2.69 -0.5" actuatorfrcrange="-0.45 0.45"/>
            <geom type="mesh" rgba="0.890196 0.890196 0.913725 1" mesh="bl_calf"/>
            <geom pos="0 0 -0.065864" quat="1 0 0 0" type="mesh" rgba="0.890196 0.890196 0.913725 1" mesh="bl_foot"/>
          </body>
        </body>
      </body>
    </body>
  </worldbody>

  <actuator>
    <!-- FR -->
    <motor name="fr_hip" joint="fr_hip_joint" gear="1" ctrllimited="true" ctrlrange="-100 100"/>
    <motor name="fr_thigh" joint="fr_thigh_joint" gear="1" ctrllimited="true" ctrlrange="-100 100"/>
    <motor name="fr_calf" joint="fr_calf_joint" gear="1" ctrllimited="true" ctrlrange="-100 100"/>
    <!-- FL -->
    <motor name="fl_hip" joint="fl_hip_joint" gear="1" ctrllimited="true" ctrlrange="-100 100"/>
    <motor name="fl_thigh" joint="fl_thigh_joint" gear="1" ctrllimited="true" ctrlrange="-100 100"/>
    <motor name="fl_calf" joint="fl_calf_joint" gear="1" ctrllimited="true" ctrlrange="-100 100"/>
    <!-- BR -->
    <motor name="br_hip" joint="br_hip_joint" gear="1" ctrllimited="true" ctrlrange="-100 100"/>
    <motor name="br_thigh" joint="br_thigh_joint" gear="1" ctrllimited="true" ctrlrange="-100 100"/>
    <motor name="br_calf" joint="br_calf_joint" gear="1" ctrllimited="true" ctrlrange="-100 100"/>
    <!-- BL -->
    <motor name="bl_hip" joint="bl_hip_joint" gear="1" ctrllimited="true" ctrlrange="-100 100"/>
    <motor name="bl_thigh" joint="bl_thigh_joint" gear="1" ctrllimited="true" ctrlrange="-100 100"/>
    <motor name="bl_calf" joint="bl_calf_joint" gear="1" ctrllimited="true" ctrlrange="-100 100"/>
  </actuator>
  <sensor>
        <jointpos name="FL_hip_pos"     joint="fl_hip_joint"/>
        <jointpos name="FL_thigh_pos"   joint="fl_thigh_joint"/>
        <jointpos name="FL_calf_pos"    joint="fl_calf_joint"/>
        <jointpos name="FR_hip_pos"     joint="fr_hip_joint"/>
        <jointpos name="FR_thigh_pos"   joint="fr_thigh_joint"/>
        <jointpos name="FR_calf_pos"    joint="fr_calf_joint"/>
        <jointpos name="BL_hip_pos"     joint="bl_hip_joint"/>
        <jointpos name="BL_thigh_pos"   joint="bl_thigh_joint"/>
        <jointpos name="BL_calf_pos"    joint="bl_calf_joint"/>
        <jointpos name="BR_hip_pos"     joint="br_hip_joint"/>
        <jointpos name="BR_thigh_pos"   joint="br_thigh_joint"/>
        <jointpos name="BR_calf_pos"    joint="br_calf_joint" />

        <jointvel name="FL_hip_vel"     joint="fl_hip_joint"/>
        <jointvel name="FL_thigh_vel"   joint="fl_thigh_joint"/>
        <jointvel name="FL_calf_vel"    joint="fl_calf_joint"/>
        <jointvel name="FR_hip_vel"     joint="fr_hip_joint"/>
        <jointvel name="FR_thigh_vel"   joint="fr_thigh_joint"/>
        <jointvel name="FR_calf_vel"    joint="fr_calf_joint"/>
        <jointvel name="BL_hip_vel"     joint="bl_hip_joint"/>
        <jointvel name="BL_thigh_vel"   joint="bl_thigh_joint"/>
        <jointvel name="BL_calf_vel"    joint="bl_calf_joint"/>
        <jointvel name="BR_hip_vel"     joint="br_hip_joint"/>
        <jointvel name="BR_thigh_vel"   joint="br_thigh_joint"/>
        <jointvel name="BR_calf_vel"    joint="br_calf_joint"/>
    </sensor>
</mujoco>
